Workbook

Sheet 반출증
A2: 발 행 부 서 | L2: 관 리 부 서
A3: 담 당 | C3: 심의 | E3: 팀 장 | L3: 담 당 | N3: 심의 | P3: 팀 장
A8: NO. 환경- | C8: =#REF!+1 -> #REF! | E8: (일시.영구)물품 반출(입)증
K10: 45973
A12: =VLOOKUP(A18,'품명,업체,단위'!$B$1:$E$45,2,0) -> 에이슨텍코퍼레이션 | I12: 귀하
B15: 하기물품을 ( 영구 )반출(입)함을 허가함.
A17: 품 명 | E17: 규 격 | J17: 단 위 | L17: 수 량 | N17: 비 고
A18: 잡철 | E18: =IF(ISERROR(VLOOKUP(A18,'품명,업체,단위'!$B$1:$E$45,4,0)),"",VLOOKUP(A18,'품명,업체,단위'!$B$1:$E$45,4,0)) -> 10 톤 | J18: =IF(ISERROR(VLOOKUP(A18,'품명,업체,단위'!$B$1:$E$45,3,0)),"",VLOOKUP(A18,'품명,업체,단위'!$B$1:$E$45,3,0)) -> kg | L18: 3960
E19: =IF(ISERROR(VLOOKUP(A19,'품명,업체,단위'!$B$1:$E$45,4,0)),"",VLOOKUP(A19,'품명,업체,단위'!$B$1:$E$45,4,0)) | J19: =IF(ISERROR(VLOOKUP(A19,'품명,업체,단위'!$B$1:$E$45,3,0)),"",VLOOKUP(A19,'품명,업체,단위'!$B$1:$E$45,3,0))
E20: =IF(ISERROR(VLOOKUP(A20,'품명,업체,단위'!$B$1:$E$45,4,0)),"",VLOOKUP(A20,'품명,업체,단위'!$B$1:$E$45,4,0)) | J20: =IF(ISERROR(VLOOKUP(A20,'품명,업체,단위'!$B$1:$E$45,3,0)),"",VLOOKUP(A20,'품명,업체,단위'!$B$1:$E$45,3,0))
E21: =IF(ISERROR(VLOOKUP(A21,'품명,업체,단위'!$B$1:$E$45,4,0)),"",VLOOKUP(A21,'품명,업체,단위'!$B$1:$E$45,4,0)) | J21: =IF(ISERROR(VLOOKUP(A21,'품명,업체,단위'!$B$1:$E$45,3,0)),"",VLOOKUP(A21,'품명,업체,단위'!$B$1:$E$45,3,0))
E22: =IF(ISERROR(VLOOKUP(A22,'품명,업체,단위'!$B$1:$E$45,4,0)),"",VLOOKUP(A22,'품명,업체,단위'!$B$1:$E$45,4,0)) | J22: =IF(ISERROR(VLOOKUP(A22,'품명,업체,단위'!$B$1:$E$45,3,0)),"",VLOOKUP(A22,'품명,업체,단위'!$B$1:$E$45,3,0))
E23: =IF(ISERROR(VLOOKUP(A23,'품명,업체,단위'!$B$1:$E$45,4,0)),"",VLOOKUP(A23,'품명,업체,단위'!$B$1:$E$45,4,0)) | J23: =IF(ISERROR(VLOOKUP(A23,'품명,업체,단위'!$B$1:$E$45,3,0)),"",VLOOKUP(A23,'품명,업체,단위'!$B$1:$E$45,3,0))
E24: =IF(ISERROR(VLOOKUP(A24,'품명,업체,단위'!$B$1:$E$45,4,0)),"",VLOOKUP(A24,'품명,업체,단위'!$B$1:$E$45,4,0)) | J24: =IF(ISERROR(VLOOKUP(A24,'품명,업체,단위'!$B$1:$E$45,3,0)),"",VLOOKUP(A24,'품명,업체,단위'!$B$1:$E$45,3,0))
E25: =IF(ISERROR(VLOOKUP(A25,'품명,업체,단위'!$B$1:$E$45,4,0)),"",VLOOKUP(A25,'품명,업체,단위'!$B$1:$E$45,4,0)) | J25: =IF(ISERROR(VLOOKUP(A25,'품명,업체,단위'!$B$1:$E$45,3,0)),"",VLOOKUP(A25,'품명,업체,단위'!$B$1:$E$45,3,0))
E26: =IF(ISERROR(VLOOKUP(A26,'품명,업체,단위'!$B$1:$E$45,4,0)),"",VLOOKUP(A26,'품명,업체,단위'!$B$1:$E$45,4,0)) | J26: =IF(ISERROR(VLOOKUP(A26,'품명,업체,단위'!$B$1:$E$45,3,0)),"",VLOOKUP(A26,'품명,업체,단위'!$B$1:$E$45,3,0))
E27: =IF(ISERROR(VLOOKUP(A27,'품명,업체,단위'!$B$1:$E$45,4,0)),"",VLOOKUP(A27,'품명,업체,단위'!$B$1:$E$45,4,0)) | J27: =IF(ISERROR(VLOOKUP(A27,'품명,업체,단위'!$B$1:$E$45,3,0)),"",VLOOKUP(A27,'품명,업체,단위'!$B$1:$E$45,3,0))
E28: =IF(ISERROR(VLOOKUP(A28,'품명,업체,단위'!$B$1:$E$45,4,0)),"",VLOOKUP(A28,'품명,업체,단위'!$B$1:$E$45,4,0)) | J28: =IF(ISERROR(VLOOKUP(A28,'품명,업체,단위'!$B$1:$E$45,3,0)),"",VLOOKUP(A28,'품명,업체,단위'!$B$1:$E$45,3,0))
A29: 합 계 | L29: =SUM(L18:M28) -> 3960
A30: 반출년월일 | E30: 2 0 2 5 년 월 일 시 분 | N30: 정 문
N31: 확인인
N32: 정 문
N33: 확인인

Sheet 품명,업체,단위
B1: 자투리/트림 | C1: 에이슨텍코퍼레이션 | D1: kg | E1: 25 톤 | G1: 타포린 | H1: 당사 상차 진행
B2: PE 스크랩 "떡" | C2: 에이슨텍코퍼레이션 | D2: kg | E2: 10 톤 | G2: 플라스틱 | H2: 순수 PE아님, 일명 "떡", 주재료 MSDS 첨부
B3: PE 스크랩 "필름" | C3: 에이슨텍코퍼레이션 | D3: kg | E3: 10 톤 | F3: 올바로 | H3: 순수 PE아님, 압축, 주재료 MSDS 첨부, 이전 합지로 배출
B4: EVOH 스크랩 | C4: 에이슨텍코퍼레이션 | D4: kg | E4: 10 톤 | F4: 올바로 | H4: 순수 EVOH아님, 일명 "떡", 주재료 MSDS 첨부
B5: 합지 | C5: 에이슨텍코퍼레이션 | D5: kg | E5: 10 톤 | F5: 올바로 | H5: 불량 제품(톤백), 예상량 계산시 PE 필름량 일부 포함
B6: 합지미미 | C6: 에이슨텍코퍼레이션 | D6: kg | E6: 10 톤 | F6: 올바로 | H6: 롤 혹은 압축 포장, 종이, 알루미늄 함유된 미미 비포함
B7: PE 지관 | C7: 에이슨텍코퍼레이션 | D7: kg | E7: 10 톤 | F7: 올바로 | H7: 3년치, 유색+무색 혼합, 최소 1회/년 반출
B8: PP 지관 | C8: 에이슨텍코퍼레이션 | D8: kg | E8: 10 톤 | F8: 올바로 | H8: 3년치, 최소 1회/년 반출
B9: PET/나일론 지관 | C9: 에이슨텍코퍼레이션 | D9: kg | E9: 10 톤 | F9: 올바로 | H9: 3년치, 4:1 비율, 최소 1회/년 반출
B10: 파지 | C10: 에이슨텍코퍼레이션 | D10: kg | E10: 10 톤 | G10: 종이
B11: 파지 지관 | C11: 에이슨텍코퍼레이션 | D11: kg | E11: 10 톤 | H11: 최근 4개월 배출량
B12: 레진백 | C12: 에이슨텍코퍼레이션 | D12: kg | E12: 10 톤 | H12: 1~2회/월, 이물질(레진, 비닐 등)있음
B13: 동판 고철 | C13: 에이슨텍코퍼레이션 | D13: kg | E13: 10 톤 | G13: 고철 | H13: 일회성 400원, 23.02.17 처리
B14: 잡철 | C14: 에이슨텍코퍼레이션 | D14: kg | E14: 10 톤 | H14: 전용계좌 입금
B15: 폐말통 | C15: 에이슨텍코퍼레이션 | D15: kg | E15: 10 톤 | H15: 접착제/안료 20L통
B16: 은박파 | C16: 에이슨텍코퍼레이션 | D16: kg | E16: 10 톤 | G16: AL | H16: 필름+알루미늄, 최소 1회/년 반출
B17: 롤 25kg↓ | C17: 에이슨텍코퍼레이션 | D17: kg | E17: 10 톤 | H17: 기존 고철 처리, 최소 1회/년 반출
B18: 호일, 롤 25k ↑ | C18: 에이슨텍코퍼레이션 | D18: kg | E18: 10 톤 | H18: 기존 고철 처리, 최소 1회/년 반출
B19: 폐합성수지(폴리머 A) | C19: 에이슨텍코퍼레이션 | D19: kg | E19: 10 톤
B20: 폐합성수지(폴리머 혼합) | C20: 에이슨텍코퍼레이션 | D20: kg | E20: 10 톤
B21: 폐비닐 | C21: 에이슨텍코퍼레이션 | D21: kg | E21: 10 톤
B22: 폐페인트(액상) | C22: 상록수환경 | D22: kg | E22: 7 톤 | F22: 올바로
B23: 폐유기용제(고상) | C23: 상록수환경 | D23: kg | E23: 15 톤 | F23: 올바로 | G23: 폐보루 40 파렛트일경우 배차
B24: 폐유기용제(액상) | C24: 상록수환경 | D24: kg | E24: 10 톤 | F24: 올바로
B25: 폐합성수지(연료화) | C25: 상록수환경 | D25: kg | E25: 15 톤 | F25: 올바로
B26: 폐합성수지(생활계) | C26: 상록수환경 | D26: kg | E26: 10 톤 | F26: 올바로
B27: 폐졸 2 | C27: 에이슨텍코퍼레이션 | D27: kg | E27: 15 톤
B28: 폐졸 | C28: 세영산업 | D28: kg | E28: 5 톤 | F28: 올바로
B29: 페파렛트(PE) | C29: 천안수지 | D29: kg | E29: 10 톤 | F29: 올바로
B30: 폐파래트(PP) | C30: 천안수지 | D30: kg | E30: 10 톤 | F30: 올바로
B31: 폐유(액상) | C31: 에이엠 | D31: kg | E31: 10 톤 | F31: 올바로
B32: 폐유기용제(액상)2 | C32: 에이엠 | D32: kg | E32: 10 톤 | F32: 올바로
B33: 폐파래트(목재) | C33: 유림이엔지 | D33: kg | E33: 10 톤 | F33: 올바로
B34: 폐합성수지(연료화)2 | C34: 정우산업개발 | D34: kg | E34: 10 톤 | F34: 올바로
B35: 분뇨 | C35: 천안위생 | D35: 대
B36: 폐형광등(직관) | C36: 한국조명재활용공사 | D36: EA | E36: 2.5 톤
B37: 공드럼(200L) | C37: 현대에코라인 | D37: kg | E37: 5 톤 | F37: 올바로 | H37: 200 공드럼 질량 20kg | I37: 107 | J37: =I37*20 -> 2140
B38: 공드럼(100L) | C38: 현대에코라인 | D38: kg | E38: 5 톤 | F38: 올바로 | H38: 100 공드럼 질량 10kg | I38: 72 | J38: =I38*10 -> 720
B39: 공드럼(50L) | C39: 현대에코라인 | D39: kg | E39: 5 톤 | F39: 올바로 | H39: 50 공드럼 질량 5kg
B40: 폐열매체유 | C40: ㈜화성에너텍 | D40: kg | E40: 10톤 | F40: 올바로
...

Sheet 대훈
A1: 업체 | B1: 품목 | C1: 단위 | D1: 단가 | E1: 구분 | F1: 차량 | G1: 담당 | H1: 연락처 | I1: 특이사항
A2: 상록수환경 (Allbaro + 반출증) → 세금계산서 처리 | B2: 폐합성수지(연료화) | C2: kg | D2: 180원 | E2: 처리 | F2: 15 톤 | G2: 김재현 부사장 | H2: 010-5464-8952 | I2: 집게차
B3: 폐합성수지(생활계) | C3: kg | D3: 275원 | E3: 처리 | F3: 10 톤 | G3: 김현우 팀장 | H3: 010-9237-8024 | I3: 집게차
B4: 폐유기용제(액상) | C4: kg | D4: 375원 | E4: 처리 | F4: 7 톤 | G4: 041-622-2722 | I4: 드럼
B5: 폐페인트(액상) | C5: kg | D5: 375원 | E5: 처리 | F5: 7 톤 | G5: FAX:041-622-2662 | I5: 드럼(폐잉크 액상만) - 탑에코
B6: 폐유(고상) | C6: kg | D6: 370원 | E6: 처리 | F6: 15 톤 | G6: k1600@naver.com | I6: 폐보루(톤백 10~12덩이=> 40덩이)
A7: 현대그린텍 | B7: 공드럼(200kg) | C7: kg | D7: 0 | E7: 처리 | F7: 5 톤 | G7: 김관수 부장 | H7: 010-2831-3697 | I7: 수량기입(작은차90EA, 큰차180EA)
B8: 공드럼(100kg) | C8: kg | D8: 0 | E8: 처리 | F8: 5 톤 | G8: 김재진 부장(환경) | H8: 010-7218-8456 | I8: 20kg 10kg 5kg
B9: 공드럼(50kg) | C9: kg | D9: 0 | E9: 처리 | F9: 5 톤
B10: PE 드럼 | C10: kg | D10: 0 | E10: 처리 | F10: 5 톤
A11: 한국조명재활용공사 | B11: 폐형광등(직관) | C11: EA | D11: 230원 | E11: 처리 | F11: 2.5 톤
B12: 폐형광등(CFL) | C12: EA | E12: 처리 | F12: 2.5 톤
A13: 유림이엔지 | B13: 폐파래트 | C13: 대 | D13: 15만원 | E13: 처리 | F13: 10 톤 | G13: 신현실 대표 | H13: 010-3930-6363 | I13: Allbaro, 배차, 세금계산서
A14: 세영산업 | B14: 폐졸 | C14: 대 | E14: 처리 | F14: 1 톤 | G14: 공유석 대표 | H14: 010-3302-4977 | I14: 용차사용 (200원/KG)20만원/대 1Ptt 4드럼 | J14: 회사명 : 세영산업 , 주소 : 충청북도 충주시 주덕읍 제내리 557-43 , 받는사람 : 공유석 , 연락처 : 010-3302-4977 / 043-846-2028 | V14: 무상처리

Sheet Sheet1
A1: 7월 반출내역
A2: 날짜 | B2: 업체 | C2: 내용 | D2: 수량
